INFO:     Started server process [9300]
INFO:     Waiting for application startup.
INFO:     Application startup complete.
INFO:     Uvicorn running on http://127.0.0.1:8000 (Press CTRL+C to quit)
[INFO] Reglas cargadas es-MX: 3
[INFO] Reglas cargadas es-419: 2
[INFO] Reglas cargadas en-US: 0
[ERROR] Error analizando texto
Traceback (most recent call last):
  File "D:\PROYECTOS-FLUTTER\lia-staylo\backend\.venv\Lib\site-packages\urllib3\connectionpool.py", line 534, in _make_request
    response = conn.getresponse()
               ^^^^^^^^^^^^^^^^^^
  File "D:\PROYECTOS-FLUTTER\lia-staylo\backend\.venv\Lib\site-packages\urllib3\connection.py", line 565, in getresponse
    httplib_response = super().getresponse()
                       ^^^^^^^^^^^^^^^^^^^^^
  File "C:\Users\migue\AppData\Local\Programs\Python\Python311\Lib\http\client.py", line 1395, in getresponse
    response.begin()
  File "C:\Users\migue\AppData\Local\Programs\Python\Python311\Lib\http\client.py", line 325, in begin
    version, status, reason = self._read_status()
                              ^^^^^^^^^^^^^^^^^^^
  File "C:\Users\migue\AppData\Local\Programs\Python\Python311\Lib\http\client.py", line 286, in _read_status
    line = str(self.fp.readline(_MAXLINE + 1), "iso-8859-1")
               ^^^^^^^^^^^^^^^^^^^^^^^^^^^^^^
  File "C:\Users\migue\AppData\Local\Programs\Python\Python311\Lib\socket.py", line 706, in readinto
    return self._sock.recv_into(b)
           ^^^^^^^^^^^^^^^^^^^^^^^
TimeoutError: timed out

The above exception was the direct cause of the following exception:

Traceback (most recent call last):
  File "D:\PROYECTOS-FLUTTER\lia-staylo\backend\.venv\Lib\site-packages\requests\adapters.py", line 667, in send
    resp = conn.urlopen(
           ^^^^^^^^^^^^^
  File "D:\PROYECTOS-FLUTTER\lia-staylo\backend\.venv\Lib\site-packages\urllib3\connectionpool.py", line 841, in urlopen
    retries = retries.increment(
              ^^^^^^^^^^^^^^^^^^
  File "D:\PROYECTOS-FLUTTER\lia-staylo\backend\.venv\Lib\site-packages\urllib3\util\retry.py", line 474, in increment
    raise reraise(type(error), error, _stacktrace)
          ^^^^^^^^^^^^^^^^^^^^^^^^^^^^^^^^^^^^^^^^
  File "D:\PROYECTOS-FLUTTER\lia-staylo\backend\.venv\Lib\site-packages\urllib3\util\util.py", line 39, in reraise
    raise value
  File "D:\PROYECTOS-FLUTTER\lia-staylo\backend\.venv\Lib\site-packages\urllib3\connectionpool.py", line 787, in urlopen
    response = self._make_request(
               ^^^^^^^^^^^^^^^^^^^
  File "D:\PROYECTOS-FLUTTER\lia-staylo\backend\.venv\Lib\site-packages\urllib3\connectionpool.py", line 536, in _make_request
    self._raise_timeout(err=e, url=url, timeout_value=read_timeout)
  File "D:\PROYECTOS-FLUTTER\lia-staylo\backend\.venv\Lib\site-packages\urllib3\connectionpool.py", line 367, in _raise_timeout
    raise ReadTimeoutError(
urllib3.exceptions.ReadTimeoutError: HTTPConnectionPool(host='127.0.0.1', port=8081): Read timed out. (read timeout=30)

During handling of the above exception, another exception occurred:

Traceback (most recent call last):
  File "D:\PROYECTOS-FLUTTER\lia-staylo\backend\main.py", line 288, in lt_check
    resp = requests.post(url, data={"language": lt_lang, "text": text}, timeout=30)
           ^^^^^^^^^^^^^^^^^^^^^^^^^^^^^^^^^^^^^^^^^^^^^^^^^^^^^^^^^^^^^^^^^^^^^^^^
  File "D:\PROYECTOS-FLUTTER\lia-staylo\backend\.venv\Lib\site-packages\requests\api.py", line 115, in post
    return request("post", url, data=data, json=json, **kwargs)
           ^^^^^^^^^^^^^^^^^^^^^^^^^^^^^^^^^^^^^^^^^^^^^^^^^^^^
  File "D:\PROYECTOS-FLUTTER\lia-staylo\backend\.venv\Lib\site-packages\requests\api.py", line 59, in request
    return session.request(method=method, url=url, **kwargs)
           ^^^^^^^^^^^^^^^^^^^^^^^^^^^^^^^^^^^^^^^^^^^^^^^^^
  File "D:\PROYECTOS-FLUTTER\lia-staylo\backend\.venv\Lib\site-packages\requests\sessions.py", line 589, in request
    resp = self.send(prep, **send_kwargs)
           ^^^^^^^^^^^^^^^^^^^^^^^^^^^^^^
  File "D:\PROYECTOS-FLUTTER\lia-staylo\backend\.venv\Lib\site-packages\requests\sessions.py", line 703, in send
    r = adapter.send(request, **kwargs)
        ^^^^^^^^^^^^^^^^^^^^^^^^^^^^^^^
  File "D:\PROYECTOS-FLUTTER\lia-staylo\backend\.venv\Lib\site-packages\requests\adapters.py", line 713, in send
    raise ReadTimeout(e, request=request)
requests.exceptions.ReadTimeout: HTTPConnectionPool(host='127.0.0.1', port=8081): Read timed out. (read timeout=30)

The above exception was the direct cause of the following exception:

Traceback (most recent call last):
  File "D:\PROYECTOS-FLUTTER\lia-staylo\backend\main.py", line 458, in analyze_text
    lt_matches = lt_check(text, lang_ui)
                 ^^^^^^^^^^^^^^^^^^^^^^^
  File "D:\PROYECTOS-FLUTTER\lia-staylo\backend\main.py", line 291, in lt_check
    raise RuntimeError(f"LanguageTool no disponible en {LT_BASE}: {e}") from e
RuntimeError: LanguageTool no disponible en http://127.0.0.1:8081: HTTPConnectionPool(host='127.0.0.1', port=8081): Read timed out. (read timeout=30)
